<?xml version="1.0" ?>
<robot xmlns:xacro="http://wiki.ros.org/xacro" name="$(arg name)">
  <!-- robot name parameter -->
  <xacro:arg name="name" default="ur"/>
  <!-- import main macro -->
  <xacro:include filename="$(find ur_description)/urdf/ur_macro.xacro"/>

  <!-- possible 'ur_type' values: ur3, ur3e, ur5, ur5e, ur10, ur10e, ur16e, ur20, ur30 -->
  <!-- the default value should raise an error in case this was called without defining the type -->
  <xacro:arg name="ur_type" default="ur5x"/>

  <!-- parameters -->
  <xacro:arg name="tf_prefix" default="" />
  <xacro:arg name="joint_limit_parameters_file" default="$(find ur_description)/config/$(arg ur_type)/joint_limits.yaml"/>
  <xacro:arg name="kinematics_params" default="$(find ur_description)/config/$(arg ur_type)/default_kinematics.yaml"/>
  <xacro:arg name="physical_params" default="$(find ur_description)/config/$(arg ur_type)/physical_parameters.yaml"/>
  <xacro:arg name="visual_params" default="$(find ur_description)/config/$(arg ur_type)/visual_parameters.yaml"/>
  <!-- <xacro:arg name="transmission_hw_interface" default=""/> -->
  <xacro:arg name="safety_limits" default="false"/>
  <xacro:arg name="safety_pos_margin" default="0.15"/>
  <xacro:arg name="safety_k_position" default="20"/>
  <!-- ros2_control related parameters -->
  <xacro:arg name="headless_mode" default="true" />
  <xacro:arg name="robot_ip" default="0.0.0.0" />
  <xacro:arg name="script_filename" default="$(find ur_robot_driver)/resources/ros_control.urscript"/>
  <xacro:arg name="output_recipe_filename" default="$(find ur_robot_driver)/resources/rtde_output_recipe.txt"/>
  <xacro:arg name="input_recipe_filename" default="$(find ur_robot_driver)/resources/rtde_input_recipe.txt"/>
  <xacro:arg name="reverse_ip" default="0.0.0.0"/>
  <xacro:arg name="script_command_port" default="50004"/>
  <xacro:arg name="reverse_port" default="50001"/>
  <xacro:arg name="script_sender_port" default="50002"/>
  <xacro:arg name="trajectory_port" default="50003"/>
  <!--   tool communication related parameters-->
  <xacro:arg name="use_tool_communication" default="true" />
  <xacro:arg name="tool_voltage" default="24" />
  <xacro:arg name="tool_parity" default="0" />
  <xacro:arg name="tool_baud_rate" default="115200" />
  <xacro:arg name="tool_stop_bits" default="1" />
  <xacro:arg name="tool_rx_idle_chars" default="1.5" />
  <xacro:arg name="tool_tx_idle_chars" default="3.5" />
  <xacro:arg name="tool_device_name" default="/tmp/ttyUR" />
  <xacro:arg name="tool_tcp_port" default="54321" />

  <!-- Simulation parameters -->
  <xacro:arg name="use_fake_hardware" default="false" />
  <xacro:arg name="mock_sensor_commands" default="false" />
  <xacro:arg name="simulation_controllers" default="" />
  <xacro:arg name="mujoco_model" default="description/scene.xml" />
  <xacro:arg name="mujoco_model_package" default="ur_sim" />
  <xacro:arg name="mujoco_viewer" default="true" />

  <!-- initial position for simulations (Fake Hardware, Gazebo, Ignition) -->
  <xacro:arg name="initial_positions_file" default="$(find ur_description)/config/initial_positions.yaml"/>

  <!-- convert to property to use substitution in function -->
  <xacro:property name="initial_positions_file" default="$(arg initial_positions_file)"/>

  <!-- create link fixed to the "world" -->
  <link name="world" />

  <!-- arm -->
  <xacro:ur_robot
          name="$(arg name)"
          tf_prefix="$(arg tf_prefix)"
          parent="world"
          joint_limits_parameters_file="$(arg joint_limit_parameters_file)"
          kinematics_parameters_file="$(arg kinematics_params)"
          physical_parameters_file="$(arg physical_params)"
          visual_parameters_file="$(arg visual_params)"
          safety_limits="$(arg safety_limits)"
          safety_pos_margin="$(arg safety_pos_margin)"
          safety_k_position="$(arg safety_k_position)"
  >
    <origin xyz="0 0 0" rpy="0 0 0" />          <!-- position robot in the world -->
  </xacro:ur_robot>

  <!-- wrist camera adapter and camera-->
  <xacro:include
    filename="$(find picknik_accessories)/descriptions/brackets/ur_realsense_camera_adapter/picknik_ur_camera_adapter.urdf.xacro"
  />
  <xacro:include
    filename="$(find picknik_accessories)/descriptions/sensors/realsense_d415.urdf.xacro"
  />

  <xacro:ur_realsense_camera_adapter
    prefix="$(arg tf_prefix)"
    parent="tool0"
    child_tool="realsense_camera_adapter_tool0"
    child_camera="d415_mount_link"
    rotation="0"
  />
  <xacro:realsense_d415
    parent="d415_mount_link"
    name="wrist_mounted_camera"
    use_mesh="true"
  >
    <origin xyz="0 0 0" rpy="0 0 0" />
  </xacro:realsense_d415>

  <!-- gripper and UR adapter-->
  <xacro:include
    filename="$(find robotiq_description)/urdf/ur_to_robotiq_adapter.urdf.xacro"
  />
  <xacro:include
    filename="$(find robotiq_description)/urdf/robotiq_2f_85_macro.urdf.xacro"
  />
  
  <xacro:ur_to_robotiq
    prefix="$(arg tf_prefix)"
    parent="realsense_camera_adapter_tool0"
    child="gripper_mount_link"
    rotation="0"
  />

  <link name="robotiq_85_base_link">
    <visual>
      <geometry>
        <mesh
          filename="package://robotiq_description/meshes/visual/2f_85/robotiq_base.dae"
        />
      </geometry>
    </visual>
    <collision>
      <geometry>
        <mesh
          filename="package://robotiq_description/meshes/collision/2f_85/robotiq_base.stl"
        />
      </geometry>
    </collision>
    <inertial>
      <origin rpy="0 0 0" xyz="0.0 2.274e-05 0.03232288" />
      <mass value="6.6320197e-01" />
      <inertia
        ixx="5.1617816e-04"
        ixy="2.936e-8"
        ixz="0.0"
        iyy="5.8802208e-04"
        iyz="-3.2296e-7"
        izz="3.9462776e-04"
      />
    </inertial>
  </link>
  <link name="robotiq_85_left_knuckle_link">
    <visual>
      <geometry>
        <mesh
          filename="package://robotiq_description/meshes/visual/2f_85/left_knuckle.dae"
        />
      </geometry>
    </visual>
    <collision>
      <geometry>
        <mesh
          filename="package://robotiq_description/meshes/collision/2f_85/left_knuckle.stl"
        />
      </geometry>
    </collision>
    <inertial>
      <origin rpy="0 0 0" xyz="0.01213197 0.0002 -0.00058647" />
      <mass value="1.384773208e-02" />
      <inertia
        ixx="3.5232e-7"
        ixy="0.0"
        ixz="1.1744e-7"
        iyy="2.31944e-6"
        iyz="0"
        izz="2.23136e-6"
      />
    </inertial>
  </link>
  <link name="robotiq_85_right_knuckle_link">
    <visual>
      <geometry>
        <mesh
          filename="package://robotiq_description/meshes/visual/2f_85/right_knuckle.dae"
        />
      </geometry>
    </visual>
    <collision>
      <geometry>
        <mesh
          filename="package://robotiq_description/meshes/collision/2f_85/right_knuckle.stl"
        />
      </geometry>
    </collision>
    <inertial>
      <origin rpy="0 0 0" xyz="-0.01213197 0.0002 -0.00058647" />
      <mass value="1.384773208e-02" />
      <inertia
        ixx="3.5232e-7"
        ixy="0.0"
        ixz="-1.1744e-7"
        iyy="2.31944e-6"
        iyz="0.0"
        izz="2.23136e-6"
      />
    </inertial>
  </link>
  <link name="robotiq_85_left_finger_link">
    <visual>
      <geometry>
        <mesh
          filename="package://robotiq_description/meshes/visual/2f_85/left_finger.dae"
        />
      </geometry>
    </visual>
    <collision>
      <geometry>
        <mesh
          filename="package://robotiq_description/meshes/collision/2f_85/left_finger.stl"
        />
      </geometry>
    </collision>
    <inertial>
      <origin rpy="0 0 0" xyz="0.00346899 -0.00079447 0.01867121" />
      <mass value="4.260376752e-02" />
      <inertia
        ixx="1.385792000000000e-05"
        ixy="0.0"
        ixz="-2.17264e-06"
        iyy="1.183208e-05"
        iyz="0.0"
        izz="5.19672e-06"
      />
    </inertial>
  </link>
  <link name="robotiq_85_right_finger_link">
    <visual>
      <geometry>
        <mesh
          filename="package://robotiq_description/meshes/visual/2f_85/right_finger.dae"
        />
      </geometry>
    </visual>
    <collision>
      <geometry>
        <mesh
          filename="package://robotiq_description/meshes/collision/2f_85/right_finger.stl"
        />
      </geometry>
    </collision>
    <inertial>
      <origin rpy="0 0 0" xyz="-0.00346899 -5.53e-06 0.01867121" />
      <mass value="4.260376752000000e-02" />
      <inertia
        ixx="1.385792e-05"
        ixy="0.0"
        ixz="2.17264e-06"
        iyy="1.183208e-05"
        iyz="0.0"
        izz="5.19672e-06"
      />
    </inertial>
  </link>
  <link name="robotiq_85_left_inner_knuckle_link">
    <visual>
      <geometry>
        <mesh
          filename="package://robotiq_description/meshes/visual/2f_85/left_inner_knuckle.dae"
        />
      </geometry>
    </visual>
    <collision>
      <geometry>
        <mesh
          filename="package://robotiq_description/meshes/collision/2f_85/left_inner_knuckle.stl"
        />
      </geometry>
    </collision>
    <inertial>
      <origin rpy="0 0 0" xyz="0.01897699 0.00015001 0.02247101" />
      <mass value="2.969376448e-02" />
      <inertia
        ixx="9.57136e-06"
        ixy="0.0"
        ixz="-3.93424e-06"
        iyy="8.69056e-06"
        iyz="0.0"
        izz="8.19144e-06"
      />
    </inertial>
  </link>
  <link name="robotiq_85_right_inner_knuckle_link">
    <visual>
      <geometry>
        <mesh
          filename="package://robotiq_description/meshes/visual/2f_85/right_inner_knuckle.dae"
        />
      </geometry>
    </visual>
    <collision>
      <geometry>
        <mesh
          filename="package://robotiq_description/meshes/collision/2f_85/right_inner_knuckle.stl"
        />
      </geometry>
    </collision>
    <inertial>
      <origin rpy="0 0 0" xyz="-0.01926824 5.001e-05 0.02222178" />
      <mass value="2.969376448e-02" />
      <inertia
        ixx="9.42456e-06"
        ixy="0.0"
        ixz="3.9636e-06"
        iyy="8.69056e-06"
        iyz="0.0"
        izz="8.33824e-06"
      />
    </inertial>
  </link>
  <link name="robotiq_85_left_finger_tip_link">
    <visual>
      <geometry>
        <mesh
          filename="package://robotiq_description/meshes/visual/2f_85/left_finger_tip.dae"
        />
      </geometry>
    </visual>
    <collision>
      <geometry>
        <mesh
          filename="package://robotiq_description/meshes/collision/2f_85/left_finger_tip.stl"
        />
      </geometry>
      <surface>
        <friction>
          <ode>
            <mu1>100000.0</mu1>
            <mu2>100000.0</mu2>
          </ode>
        </friction>
        <contact>
          <ode>
            <kp>1e+5</kp>
            <kd>1</kd>
            <soft_cfm>0</soft_cfm>
            <soft_erp>0.2</soft_erp>
            <minDepth>0.002</minDepth>
            <maxVel>0</maxVel>
          </ode>
        </contact>
      </surface>
    </collision>
    <inertial>
      <origin rpy="0 0 0" xyz="-0.01456706 -0.0008 0.01649701" />
      <mass value="4.268588744e-02" />
      <inertia
        ixx="1.048152e-05"
        ixy="0.0"
        ixz="3.5232e-6"
        iyy="1.197888e-05"
        iyz="0.0"
        izz="4.22784e-06"
      />
    </inertial>
  </link>
  <link name="robotiq_85_right_finger_tip_link">
    <visual>
      <geometry>
        <mesh
          filename="package://robotiq_description/meshes/visual/2f_85/right_finger_tip.dae"
        />
      </geometry>
    </visual>
    <collision>
      <geometry>
        <mesh
          filename="package://robotiq_description/meshes/collision/2f_85/right_finger_tip.stl"
        />
      </geometry>
      <surface>
        <friction>
          <ode>
            <mu1>100000.0</mu1>
            <mu2>100000.0</mu2>
          </ode>
        </friction>
        <contact>
          <ode>
            <kp>1e+5</kp>
            <kd>1</kd>
            <soft_cfm>0</soft_cfm>
            <soft_erp>0.2</soft_erp>
            <minDepth>0.002</minDepth>
            <maxVel>0</maxVel>
          </ode>
        </contact>
      </surface>
    </collision>
    <inertial>
      <origin rpy="0 0 0" xyz="0.01456706 5e-05 0.01649701" />
      <mass value="4.268588744e-02" />
      <inertia
        ixx="1.048152e-05"
        ixy="0.0"
        ixz="-3.5232e-06"
        iyy="1.197888e-05"
        iyz="0.0"
        izz="4.22784e-06"
      />
    </inertial>
  </link>
  <joint name="robotiq_85_base_joint" type="fixed">
    <parent link="gripper_mount_link" />
    <child link="robotiq_85_base_link" />
    <origin rpy="0 0 0" xyz="0 0 0" />
  </joint>
  <joint name="robotiq_85_left_knuckle_joint" type="revolute">
    <parent link="robotiq_85_base_link" />
    <child link="robotiq_85_left_knuckle_link" />
    <axis xyz="0 -1 0" />
    <origin rpy="0 0 0" xyz="0.03060114 0.0 0.05490452" />
    <limit effort="20" lower="0.0" upper="0.8" velocity="0.5" />
  </joint>
  <joint name="robotiq_85_right_knuckle_joint" type="revolute">
    <parent link="robotiq_85_base_link" />
    <child link="robotiq_85_right_knuckle_link" />
    <axis xyz="0 1 0" />
    <origin rpy="0 0 0" xyz="-0.03060114 0.0 0.05490452" />
    <limit effort="20" lower="0.0" upper="0.8" velocity="0.5" />
    <mimic joint="robotiq_85_left_knuckle_joint" multiplier="1" />
  </joint>
  <joint name="robotiq_85_left_finger_joint" type="fixed">
    <parent link="robotiq_85_left_knuckle_link" />
    <child link="robotiq_85_left_finger_link" />
    <axis xyz="0 -1 0" />
    <origin rpy="0 0 0" xyz="0.03152616 0.0 -0.00376347" />
  </joint>
  <joint name="robotiq_85_right_finger_joint" type="fixed">
    <parent link="robotiq_85_right_knuckle_link" />
    <child link="robotiq_85_right_finger_link" />
    <axis xyz="0 1 0" />
    <origin rpy="0 0 0" xyz="-0.03152616 0.0 -0.00376347" />
  </joint>
  <joint name="robotiq_85_left_inner_knuckle_joint" type="continuous">
    <parent link="robotiq_85_base_link" />
    <child link="robotiq_85_left_inner_knuckle_link" />
    <axis xyz="0 -1 0" />
    <origin rpy="0 0 0" xyz="0.0127 0.0 0.06142" />
    <mimic joint="robotiq_85_left_knuckle_joint" multiplier="1" />
  </joint>
  <joint name="robotiq_85_right_inner_knuckle_joint" type="continuous">
    <parent link="robotiq_85_base_link" />
    <child link="robotiq_85_right_inner_knuckle_link" />
    <axis xyz="0 1 0" />
    <origin rpy="0 0 0" xyz="-0.0127 0.0 0.06142" />
    <mimic joint="robotiq_85_left_knuckle_joint" multiplier="1" />
  </joint>
  <joint name="robotiq_85_left_finger_tip_joint" type="continuous">
    <parent link="robotiq_85_left_finger_link" />
    <child link="robotiq_85_left_finger_tip_link" />
    <axis xyz="0 -1 0" />
    <origin rpy="0 0 0" xyz="0.00563134 0.0 0.04718515" />
    <mimic joint="robotiq_85_left_knuckle_joint" multiplier="-1" />
  </joint>
  <joint name="robotiq_85_right_finger_tip_joint" type="continuous">
    <parent link="robotiq_85_right_finger_link" />
    <child link="robotiq_85_right_finger_tip_link" />
    <axis xyz="0 1 0" />
    <origin rpy="0 0 0" xyz="-0.00563134 0.0 0.04718515" />
    <mimic joint="robotiq_85_left_knuckle_joint" multiplier="-1" />
  </joint>



  <!-- This link aligns the axes of the grasp frame to our required convention for motion planning tasks. -->
  <link name="grasp_link" />
  <joint name="$grasp_link_joint" type="fixed">
    <parent link="robotiq_85_base_link" />
    <child link="grasp_link" />
    <origin xyz="0.0 0.0 0.134" rpy="0.0 0.0 ${pi}" />
  </joint>


  <ros2_control name="ur_sim" type="system">
    <hardware>
      <plugin>picknik_mujoco_ros/MujocoSystem</plugin>
      <param name="mujoco_model">$(arg mujoco_model)</param>
      <param name="mujoco_model_package">$(arg mujoco_model_package)</param>
      <!-- The rate <camera> data is published at -->
      <param name="render_publish_rate">10</param>
      <!-- The rate transforms to <site> poses are published at -->
      <param name="tf_publish_rate">60</param>
      <!-- The rate <rangefinder> data is published at -->
      <param name="lidar_publish_rate">10</param>
      <!-- Whether to launch the MuJoCo interactive viewer -->
      <param name="mujoco_viewer">$(arg mujoco_viewer)</param>
    </hardware>
  </ros2_control>
</robot>
