<?xml version="1.0" ?>
<!-- =================================================================================== -->
<!-- |    This document was autogenerated by xacro from /home/arthur/user_ws/install/picknik_009_ur5e_config/share/picknik_009_ur5e_config/description/picknik_009_ur5e.urdf.xacro | -->
<!-- |    EDITING THIS FILE BY HAND IS NOT RECOMMENDED                                 | -->
<!-- =================================================================================== -->
<robot name="ur5e">
  <!--
    Base UR robot series xacro macro.

    NOTE this is NOT a URDF. It cannot directly be loaded by consumers
    expecting a flattened '.urdf' file. See the top-level '.xacro' for that
    (but note that .xacro must still be processed by the xacro command).

    This file models the base kinematic chain of a UR robot, which then gets
    parameterised by various configuration files to convert it into a UR3(e),
    UR5(e), UR10(e) or UR16e.

    NOTE the default kinematic parameters (i.e., link lengths, frame locations,
    offsets, etc) do not correspond to any particular robot. They are defaults
    only. There WILL be non-zero offsets between the Forward Kinematics results
    in TF (i.e., robot_state_publisher) and the values reported by the Teach
    Pendant.

    For accurate (and robot-specific) transforms, the 'kinematics_parameters_file'
    parameter MUST point to a .yaml file containing the appropriate values for
    the targeted robot.

    If using the UniversalRobots/Universal_Robots_ROS_Driver, follow the steps
    described in the readme of that repository to extract the kinematic
    calibration from the controller and generate the required .yaml file.

    Main author of the migration to yaml configs Ludovic Delval.

    Contributors to previous versions (in no particular order)

     - Denis Stogl
     - Lovro Ivanov
     - Felix Messmer
     - Kelsey Hawkins
     - Wim Meeussen
     - Shaun Edwards
     - Nadia Hammoudeh Garcia
     - Dave Hershberger
     - G. vd. Hoorn
     - Philip Long
     - Dave Coleman
     - Miguel Prada
     - Mathias Luedtke
     - Marcel Schnirring
     - Felix von Drigalski
     - Felix Exner
     - Jimmy Da Silva
     - Ajit Krisshna N L
     - Muhammad Asif Rana
  -->
  <!--
    NOTE the macro defined in this file is NOT part of the public API of this
          package. Users CANNOT rely on this file being available, or stored in
          this location. Nor can they rely on the existence of the macro.
  -->
  <!-- create link fixed to the "world" -->
  <link name="world"/>
  <ros2_control name="ur5e" type="system">
    <hardware>
      <plugin>mock_components/GenericSystem</plugin>
      <param name="mock_sensor_commands">False</param>
      <param name="state_following_offset">0.0</param>
      <param name="calculate_dynamics">true</param>
    </hardware>
    <joint name="shoulder_pan_joint">
      <command_interface name="position"/>
      <command_interface name="velocity"/>
      <state_interface name="position">
        <!-- initial position for the FakeSystem and simulation -->
        <param name="initial_value">0.0</param>
      </state_interface>
      <state_interface name="velocity"/>
      <state_interface name="effort"/>
    </joint>
    <joint name="shoulder_lift_joint">
      <command_interface name="position"/>
      <command_interface name="velocity"/>
      <state_interface name="position">
        <!-- initial position for the FakeSystem and simulation -->
        <param name="initial_value">-1.57</param>
      </state_interface>
      <state_interface name="velocity"/>
      <state_interface name="effort"/>
    </joint>
    <joint name="elbow_joint">
      <command_interface name="position"/>
      <command_interface name="velocity"/>
      <state_interface name="position">
        <!-- initial position for the FakeSystem and simulation -->
        <param name="initial_value">0.0</param>
      </state_interface>
      <state_interface name="velocity"/>
      <state_interface name="effort"/>
    </joint>
    <joint name="wrist_1_joint">
      <command_interface name="position"/>
      <command_interface name="velocity"/>
      <state_interface name="position">
        <!-- initial position for the FakeSystem and simulation -->
        <param name="initial_value">-1.57</param>
      </state_interface>
      <state_interface name="velocity"/>
      <state_interface name="effort"/>
    </joint>
    <joint name="wrist_2_joint">
      <command_interface name="position"/>
      <command_interface name="velocity"/>
      <state_interface name="position">
        <!-- initial position for the FakeSystem and simulation -->
        <param name="initial_value">0.0</param>
      </state_interface>
      <state_interface name="velocity"/>
      <state_interface name="effort"/>
    </joint>
    <joint name="wrist_3_joint">
      <command_interface name="position"/>
      <command_interface name="velocity"/>
      <state_interface name="position">
        <!-- initial position for the FakeSystem and simulation -->
        <param name="initial_value">0.0</param>
      </state_interface>
      <state_interface name="velocity"/>
      <state_interface name="effort"/>
    </joint>
    <sensor name="tcp_fts_sensor">
      <state_interface name="force.x"/>
      <state_interface name="force.y"/>
      <state_interface name="force.z"/>
      <state_interface name="torque.x"/>
      <state_interface name="torque.y"/>
      <state_interface name="torque.z"/>
    </sensor>
    <sensor name="tcp_pose">
      <state_interface name="position.x"/>
      <state_interface name="position.y"/>
      <state_interface name="position.z"/>
      <state_interface name="orientation.x"/>
      <state_interface name="orientation.y"/>
      <state_interface name="orientation.z"/>
      <state_interface name="orientation.w"/>
    </sensor>
    <!-- NOTE The following are joints used only for testing with fake hardware and will change in the future -->
    <gpio name="speed_scaling">
      <state_interface name="speed_scaling_factor"/>
      <param name="initial_speed_scaling_factor">1</param>
      <command_interface name="target_speed_fraction_cmd"/>
      <command_interface name="target_speed_fraction_async_success"/>
    </gpio>
    <gpio name="gpio">
      <command_interface name="standard_digital_output_cmd_0"/>
      <command_interface name="standard_digital_output_cmd_1"/>
      <command_interface name="standard_digital_output_cmd_2"/>
      <command_interface name="standard_digital_output_cmd_3"/>
      <command_interface name="standard_digital_output_cmd_4"/>
      <command_interface name="standard_digital_output_cmd_5"/>
      <command_interface name="standard_digital_output_cmd_6"/>
      <command_interface name="standard_digital_output_cmd_7"/>
      <command_interface name="standard_digital_output_cmd_8"/>
      <command_interface name="standard_digital_output_cmd_9"/>
      <command_interface name="standard_digital_output_cmd_10"/>
      <command_interface name="standard_digital_output_cmd_11"/>
      <command_interface name="standard_digital_output_cmd_12"/>
      <command_interface name="standard_digital_output_cmd_13"/>
      <command_interface name="standard_digital_output_cmd_14"/>
      <command_interface name="standard_digital_output_cmd_15"/>
      <command_interface name="standard_digital_output_cmd_16"/>
      <command_interface name="standard_digital_output_cmd_17"/>
      <command_interface name="standard_analog_output_cmd_0"/>
      <command_interface name="standard_analog_output_cmd_1"/>
      <command_interface name="analog_output_domain_cmd"/>
      <command_interface name="tool_voltage_cmd"/>
      <command_interface name="io_async_success"/>
      <state_interface name="digital_output_0"/>
      <state_interface name="digital_output_1"/>
      <state_interface name="digital_output_2"/>
      <state_interface name="digital_output_3"/>
      <state_interface name="digital_output_4"/>
      <state_interface name="digital_output_5"/>
      <state_interface name="digital_output_6"/>
      <state_interface name="digital_output_7"/>
      <state_interface name="digital_output_8"/>
      <state_interface name="digital_output_9"/>
      <state_interface name="digital_output_10"/>
      <state_interface name="digital_output_11"/>
      <state_interface name="digital_output_12"/>
      <state_interface name="digital_output_13"/>
      <state_interface name="digital_output_14"/>
      <state_interface name="digital_output_15"/>
      <state_interface name="digital_output_16"/>
      <state_interface name="digital_output_17"/>
      <state_interface name="digital_input_0"/>
      <state_interface name="digital_input_1"/>
      <state_interface name="digital_input_2"/>
      <state_interface name="digital_input_3"/>
      <state_interface name="digital_input_4"/>
      <state_interface name="digital_input_5"/>
      <state_interface name="digital_input_6"/>
      <state_interface name="digital_input_7"/>
      <state_interface name="digital_input_8"/>
      <state_interface name="digital_input_9"/>
      <state_interface name="digital_input_10"/>
      <state_interface name="digital_input_11"/>
      <state_interface name="digital_input_12"/>
      <state_interface name="digital_input_13"/>
      <state_interface name="digital_input_14"/>
      <state_interface name="digital_input_15"/>
      <state_interface name="digital_input_16"/>
      <state_interface name="digital_input_17"/>
      <state_interface name="standard_analog_output_0"/>
      <state_interface name="standard_analog_output_1"/>
      <state_interface name="standard_analog_input_0"/>
      <state_interface name="standard_analog_input_1"/>
      <state_interface name="analog_io_type_0"/>
      <state_interface name="analog_io_type_1"/>
      <state_interface name="analog_io_type_2"/>
      <state_interface name="analog_io_type_3"/>
      <state_interface name="tool_mode"/>
      <state_interface name="tool_output_voltage"/>
      <state_interface name="tool_output_current"/>
      <state_interface name="tool_temperature"/>
      <state_interface name="tool_analog_input_0"/>
      <state_interface name="tool_analog_input_1"/>
      <state_interface name="tool_analog_input_type_0"/>
      <state_interface name="tool_analog_input_type_1"/>
      <state_interface name="robot_mode"/>
      <state_interface name="robot_status_bit_0"/>
      <state_interface name="robot_status_bit_1"/>
      <state_interface name="robot_status_bit_2"/>
      <state_interface name="robot_status_bit_3"/>
      <state_interface name="safety_mode"/>
      <state_interface name="safety_status_bit_0"/>
      <state_interface name="safety_status_bit_1"/>
      <state_interface name="safety_status_bit_2"/>
      <state_interface name="safety_status_bit_3"/>
      <state_interface name="safety_status_bit_4"/>
      <state_interface name="safety_status_bit_5"/>
      <state_interface name="safety_status_bit_6"/>
      <state_interface name="safety_status_bit_7"/>
      <state_interface name="safety_status_bit_8"/>
      <state_interface name="safety_status_bit_9"/>
      <state_interface name="safety_status_bit_10"/>
      <state_interface name="program_running"/>
    </gpio>
    <gpio name="payload">
      <command_interface name="mass"/>
      <command_interface name="cog.x"/>
      <command_interface name="cog.y"/>
      <command_interface name="cog.z"/>
      <command_interface name="payload_async_success"/>
    </gpio>
    <gpio name="resend_robot_program">
      <command_interface name="resend_robot_program_cmd"/>
      <command_interface name="resend_robot_program_async_success"/>
    </gpio>
    <gpio name="hand_back_control">
      <command_interface name="hand_back_control_cmd"/>
      <command_interface name="hand_back_control_async_success"/>
    </gpio>
    <gpio name="zero_ftsensor">
      <command_interface name="zero_ftsensor_cmd"/>
      <command_interface name="zero_ftsensor_async_success"/>
    </gpio>
    <gpio name="system_interface">
      <state_interface name="initialized"/>
    </gpio>
    <gpio name="get_robot_software_version">
      <state_interface name="get_version_major"/>
      <state_interface name="get_version_minor"/>
      <state_interface name="get_version_build"/>
      <state_interface name="get_version_bugfix"/>
    </gpio>
  </ros2_control>
  <!-- Add URDF transmission elements (for ros_control) -->
  <!--<xacro:ur_arm_transmission prefix="${prefix}" hw_interface="${transmission_hw_interface}" />-->
  <!-- Placeholder for ros2_control transmission which don't yet exist -->
  <!-- links -  main serial chain -->
  <link name="base_link"/>
  <link name="base_link_inertia">
    <visual>
      <origin rpy="0 0 3.141592653589793" xyz="0 0 0"/>
      <geometry>
        <mesh filename="package://ur_description/meshes/ur5e/collision/base.stl"/>
      </geometry>
    </visual>
    <collision>
      <origin rpy="0 0 3.141592653589793" xyz="0 0 0"/>
      <geometry>
        <mesh filename="package://ur_description/meshes/ur5e/collision/base.stl"/>
      </geometry>
    </collision>
    <inertial>
      <mass value="4.0"/>
      <origin rpy="0 0 0" xyz="0 0 0"/>
      <inertia ixx="0.00443333156" ixy="0.0" ixz="0.0" iyy="0.00443333156" iyz="0.0" izz="0.0072"/>
    </inertial>
  </link>
  <link name="shoulder_link">
    <visual>
      <origin rpy="0 0 3.141592653589793" xyz="0 0 0"/>
      <geometry>
        <mesh filename="package://ur_description/meshes/ur5e/collision/shoulder.stl"/>
      </geometry>
    </visual>
    <collision>
      <origin rpy="0 0 3.141592653589793" xyz="0 0 0"/>
      <geometry>
        <mesh filename="package://ur_description/meshes/ur5e/collision/shoulder.stl"/>
      </geometry>
    </collision>
    <inertial>
      <mass value="3.761"/>
      <origin rpy="0 0 0" xyz="0.0 -0.00193 -0.02561"/>
      <inertia ixx="0.010267499999999999" ixy="0" ixz="0" iyy="0.010267499999999999" iyz="0" izz="0.00666"/>
    </inertial>
  </link>
  <link name="upper_arm_link">
    <visual>
      <origin rpy="1.5707963267948966 0 -1.5707963267948966" xyz="0 0 0.138"/>
      <geometry>
        <mesh filename="package://ur_description/meshes/ur5e/collision/upperarm.stl"/>
      </geometry>
    </visual>
    <collision>
      <origin rpy="1.5707963267948966 0 -1.5707963267948966" xyz="0 0 0.138"/>
      <geometry>
        <mesh filename="package://ur_description/meshes/ur5e/collision/upperarm.stl"/>
      </geometry>
    </collision>
    <inertial>
      <mass value="8.058"/>
      <origin rpy="0 1.570796326794897 0" xyz="-0.2125 0.0 0.11336"/>
      <inertia ixx="0.13388583541666665" ixy="0" ixz="0" iyy="0.13388583541666665" iyz="0" izz="0.0151074"/>
    </inertial>
  </link>
  <link name="forearm_link">
    <visual>
      <origin rpy="1.5707963267948966 0 -1.5707963267948966" xyz="0 0 0.007"/>
      <geometry>
        <mesh filename="package://ur_description/meshes/ur5e/collision/forearm.stl"/>
      </geometry>
    </visual>
    <collision>
      <origin rpy="1.5707963267948966 0 -1.5707963267948966" xyz="0 0 0.007"/>
      <geometry>
        <mesh filename="package://ur_description/meshes/ur5e/collision/forearm.stl"/>
      </geometry>
    </collision>
    <inertial>
      <mass value="2.846"/>
      <origin rpy="0 1.570796326794897 0" xyz="-0.2422 0.0 0.0265"/>
      <inertia ixx="0.03120936758333333" ixy="0" ixz="0" iyy="0.03120936758333333" iyz="0" izz="0.004095"/>
    </inertial>
  </link>
  <link name="wrist_1_link">
    <visual>
      <origin rpy="1.5707963267948966 0 0" xyz="0 0 -0.127"/>
      <geometry>
        <mesh filename="package://ur_description/meshes/ur5e/collision/wrist1.stl"/>
      </geometry>
    </visual>
    <collision>
      <origin rpy="1.5707963267948966 0 0" xyz="0 0 -0.127"/>
      <geometry>
        <mesh filename="package://ur_description/meshes/ur5e/collision/wrist1.stl"/>
      </geometry>
    </collision>
    <inertial>
      <mass value="1.37"/>
      <origin rpy="0 0 0" xyz="0.0 -0.01634 -0.0018"/>
      <inertia ixx="0.0025599" ixy="0" ixz="0" iyy="0.0025599" iyz="0" izz="0.0021942"/>
    </inertial>
  </link>
  <link name="wrist_2_link">
    <visual>
      <origin rpy="0 0 0" xyz="0 0 -0.0997"/>
      <geometry>
        <mesh filename="package://ur_description/meshes/ur5e/collision/wrist2.stl"/>
      </geometry>
    </visual>
    <collision>
      <origin rpy="0 0 0" xyz="0 0 -0.0997"/>
      <geometry>
        <mesh filename="package://ur_description/meshes/ur5e/collision/wrist2.stl"/>
      </geometry>
    </collision>
    <inertial>
      <mass value="1.3"/>
      <origin rpy="0 0 0" xyz="0.0 0.01634 -0.0018"/>
      <inertia ixx="0.0025599" ixy="0" ixz="0" iyy="0.0025599" iyz="0" izz="0.0021942"/>
    </inertial>
  </link>
  <link name="wrist_3_link">
    <visual>
      <origin rpy="1.5707963267948966 0 0" xyz="0 0 -0.0989"/>
      <geometry>
        <mesh filename="package://ur_description/meshes/ur5e/collision/wrist3.stl"/>
      </geometry>
    </visual>
    <collision>
      <origin rpy="1.5707963267948966 0 0" xyz="0 0 -0.0989"/>
      <geometry>
        <mesh filename="package://ur_description/meshes/ur5e/collision/wrist3.stl"/>
      </geometry>
    </collision>
    <inertial>
      <mass value="0.365"/>
      <origin rpy="0 0 0" xyz="0.0 0.0 -0.001159"/>
      <inertia ixx="9.890414008333333e-05" ixy="0" ixz="0" iyy="9.890414008333333e-05" iyz="0" izz="0.0001321171875"/>
    </inertial>
  </link>
  <!-- base_joint fixes base_link to the environment -->
  <joint name="base_joint" type="fixed">
    <origin rpy="0 0 0" xyz="0 0 0"/>
    <parent link="world"/>
    <child link="base_link"/>
  </joint>
  <!-- joints - main serial chain -->
  <joint name="base_link-base_link_inertia" type="fixed">
    <parent link="base_link"/>
    <child link="base_link_inertia"/>
    <!-- 'base_link' is REP-103 aligned (so X+ forward), while the internal
           frames of the robot/controller have X+ pointing backwards.
           Use the joint between 'base_link' and 'base_link_inertia' (a dummy
           link/frame) to introduce the necessary rotation over Z (of pi rad).
      -->
    <origin rpy="0 0 3.141592653589793" xyz="0 0 0"/>
  </joint>
  <joint name="shoulder_pan_joint" type="revolute">
    <parent link="base_link_inertia"/>
    <child link="shoulder_link"/>
    <origin rpy="0 0 0" xyz="0 0 0.1625"/>
    <axis xyz="0 0 1"/>
    <limit effort="150.0" lower="-6.283185307179586" upper="6.283185307179586" velocity="0.5235987755982988"/>
    <dynamics damping="0" friction="0"/>
  </joint>
  <joint name="shoulder_lift_joint" type="revolute">
    <parent link="shoulder_link"/>
    <child link="upper_arm_link"/>
    <origin rpy="1.570796327 0 0" xyz="0 0 0"/>
    <axis xyz="0 0 1"/>
    <limit effort="150.0" lower="-6.283185307179586" upper="6.283185307179586" velocity="0.5235987755982988"/>
    <dynamics damping="0" friction="0"/>
  </joint>
  <joint name="elbow_joint" type="revolute">
    <parent link="upper_arm_link"/>
    <child link="forearm_link"/>
    <origin rpy="0 0 0" xyz="-0.425 0 0"/>
    <axis xyz="0 0 1"/>
    <limit effort="150.0" lower="-3.141592653589793" upper="3.141592653589793" velocity="0.5235987755982988"/>
    <dynamics damping="0" friction="0"/>
  </joint>
  <joint name="wrist_1_joint" type="revolute">
    <parent link="forearm_link"/>
    <child link="wrist_1_link"/>
    <origin rpy="0 0 0" xyz="-0.3922 0 0.1333"/>
    <axis xyz="0 0 1"/>
    <limit effort="28.0" lower="-6.283185307179586" upper="6.283185307179586" velocity="1.0471975511965976"/>
    <dynamics damping="0" friction="0"/>
  </joint>
  <joint name="wrist_2_joint" type="revolute">
    <parent link="wrist_1_link"/>
    <child link="wrist_2_link"/>
    <origin rpy="1.570796327 0 0" xyz="0 -0.0997 -2.044881182297852e-11"/>
    <axis xyz="0 0 1"/>
    <limit effort="28.0" lower="-6.283185307179586" upper="6.283185307179586" velocity="1.0471975511965976"/>
    <dynamics damping="0" friction="0"/>
  </joint>
  <joint name="wrist_3_joint" type="revolute">
    <parent link="wrist_2_link"/>
    <child link="wrist_3_link"/>
    <origin rpy="1.570796326589793 3.141592653589793 3.141592653589793" xyz="0 0.0996 -2.042830148012698e-11"/>
    <axis xyz="0 0 1"/>
    <limit effort="28.0" lower="-6.283185307179586" upper="6.283185307179586" velocity="1.0471975511965976"/>
    <dynamics damping="0" friction="0"/>
  </joint>
  <link name="ft_frame"/>
  <joint name="wrist_3_link-ft_frame" type="fixed">
    <parent link="wrist_3_link"/>
    <child link="ft_frame"/>
    <origin rpy="3.141592653589793 0 0" xyz="0 0 0"/>
  </joint>
  <!-- ROS-Industrial 'base' frame - base_link to UR 'Base' Coordinates transform -->
  <link name="base"/>
  <joint name="base_link-base_fixed_joint" type="fixed">
    <!-- Note the rotation over Z of pi radians - as base_link is REP-103
           aligned (i.e., has X+ forward, Y+ left and Z+ up), this is needed
           to correctly align 'base' with the 'Base' coordinate system of
           the UR controller.
      -->
    <origin rpy="0 0 3.141592653589793" xyz="0 0 0"/>
    <parent link="base_link"/>
    <child link="base"/>
  </joint>
  <!-- ROS-Industrial 'flange' frame - attachment point for EEF models -->
  <link name="flange"/>
  <joint name="wrist_3-flange" type="fixed">
    <parent link="wrist_3_link"/>
    <child link="flange"/>
    <origin rpy="0 -1.5707963267948966 -1.5707963267948966" xyz="0 0 0"/>
  </joint>
  <!-- ROS-Industrial 'tool0' frame - all-zeros tool frame -->
  <link name="tool0"/>
  <joint name="flange-tool0" type="fixed">
    <!-- default toolframe - X+ left, Y+ up, Z+ front -->
    <origin rpy="1.5707963267948966 0 1.5707963267948966" xyz="0 0 0"/>
    <parent link="flange"/>
    <child link="tool0"/>
  </joint>
  <material name="aluminum">
    <color rgba="0.5 0.5 0.5 1"/>
  </material>
  <material name="plastic">
    <color rgba="0.1 0.1 0.1 1"/>
  </material>
  <joint name="realsense_camera_adapter_joint" type="fixed">
    <!-- The parent link must be read from the robot model it is attached to. -->
    <parent link="tool0"/>
    <child link="realsense_camera_adapter_link"/>
    <origin rpy="0 0 0" xyz="0 0 0"/>
  </joint>
  <link name="realsense_camera_adapter_link">
    <visual>
      <origin rpy="0 0 0" xyz="0 0 0"/>
      <geometry>
        <mesh filename="package://picknik_accessories/descriptions/brackets/ur_realsense_camera_adapter/picknik_ur5_realsense_camera_adapter_rev2_collision.stl"/>
      </geometry>
    </visual>
    <collision>
      <origin rpy="0 0 0" xyz="0 0 0"/>
      <geometry>
        <mesh filename="package://picknik_accessories/descriptions/brackets/ur_realsense_camera_adapter/picknik_ur5_realsense_camera_adapter_rev2_collision.stl"/>
      </geometry>
    </collision>
  </link>
  <link name="realsense_camera_adapter_tool0"/>
  <joint name="realsense_camera_adapter_tool0_joint" type="fixed">
    <parent link="realsense_camera_adapter_link"/>
    <child link="realsense_camera_adapter_tool0"/>
    <origin rpy="0 0 0" xyz="0 0 0.007"/>
  </joint>
  <link name="d415_mount_link"/>
  <joint name="d415_mount_joint" type="fixed">
    <parent link="realsense_camera_adapter_link"/>
    <child link="d415_mount_link"/>
    <origin rpy="0 -1.4660765716752369 1.5707963267948966" xyz="0 -0.067 0.0171"/>
  </joint>
  <link name="l515_mount_link"/>
  <joint name="l515_mount_joint" type="fixed">
    <parent link="realsense_camera_adapter_link"/>
    <child link="l515_mount_link"/>
    <origin rpy="0 -1.4660765716752369 1.5707963267948966" xyz="0 -0.0406 0.0173"/>
  </joint>
  <!-- camera body, with origin at bottom screw mount -->
  <joint name="wrist_mounted_camera_joint" type="fixed">
    <origin rpy="0 0 0" xyz="0 0 0"/>
    <parent link="d415_mount_link"/>
    <child link="wrist_mounted_camera_bottom_screw_frame"/>
  </joint>
  <link name="wrist_mounted_camera_bottom_screw_frame"/>
  <joint name="wrist_mounted_camera_link_joint" type="fixed">
    <origin rpy="0 0 0" xyz="0 0.02 0.0115"/>
    <parent link="wrist_mounted_camera_bottom_screw_frame"/>
    <child link="wrist_mounted_camera_link"/>
  </joint>
  <link name="wrist_mounted_camera_link">
    <visual>
      <origin rpy="0 0 0" xyz="0 -0.02 0"/>
      <geometry>
        <box size="0.02005 0.099 0.023"/>
      </geometry>
      <material name="rs_aluminum">
        <color rgba="0.5 0.5 0.5 1.0"/>
      </material>
    </visual>
    <collision>
      <origin rpy="0 0 0" xyz="0 -0.02 0"/>
      <geometry>
        <box size="0.02005 0.099 0.023"/>
      </geometry>
    </collision>
    <inertial>
      <mass value="0.072"/>
      <!-- The following are not reliable values, and should not be used for modeling -->
      <origin xyz="0 0 0"/>
      <inertia ixx="0.003881243" ixy="0.0" ixz="0.0" iyy="0.000498940" iyz="0.0" izz="0.003879257"/>
    </inertial>
  </link>
  <!-- camera depth joints and links -->
  <joint name="wrist_mounted_camera_depth_joint" type="fixed">
    <origin rpy="0 0 0" xyz="0 0 0"/>
    <parent link="wrist_mounted_camera_link"/>
    <child link="wrist_mounted_camera_depth_frame"/>
  </joint>
  <link name="wrist_mounted_camera_depth_frame"/>
  <joint name="wrist_mounted_camera_depth_optical_joint" type="fixed">
    <origin rpy="-1.5707963267948966 0 -1.5707963267948966" xyz="0 0 0"/>
    <parent link="wrist_mounted_camera_depth_frame"/>
    <child link="wrist_mounted_camera_depth_optical_frame"/>
  </joint>
  <link name="wrist_mounted_camera_depth_optical_frame"/>
  <!-- camera left IR joints and links -->
  <joint name="wrist_mounted_camera_infra1_joint" type="fixed">
    <origin rpy="0 0 0" xyz="0 0.0 0"/>
    <parent link="wrist_mounted_camera_link"/>
    <child link="wrist_mounted_camera_infra1_frame"/>
  </joint>
  <link name="wrist_mounted_camera_infra1_frame"/>
  <joint name="wrist_mounted_camera_infra1_optical_joint" type="fixed">
    <origin rpy="-1.5707963267948966 0 -1.5707963267948966" xyz="0 0 0"/>
    <parent link="wrist_mounted_camera_infra1_frame"/>
    <child link="wrist_mounted_camera_infra1_optical_frame"/>
  </joint>
  <link name="wrist_mounted_camera_infra1_optical_frame"/>
  <!-- camera right IR joints and links -->
  <joint name="wrist_mounted_camera_infra2_joint" type="fixed">
    <origin rpy="0 0 0" xyz="0 -0.055 0"/>
    <parent link="wrist_mounted_camera_link"/>
    <child link="wrist_mounted_camera_infra2_frame"/>
  </joint>
  <link name="wrist_mounted_camera_infra2_frame"/>
  <joint name="wrist_mounted_camera_infra2_optical_joint" type="fixed">
    <origin rpy="-1.5707963267948966 0 -1.5707963267948966" xyz="0 0 0"/>
    <parent link="wrist_mounted_camera_infra2_frame"/>
    <child link="wrist_mounted_camera_infra2_optical_frame"/>
  </joint>
  <link name="wrist_mounted_camera_infra2_optical_frame"/>
  <!-- camera color joints and links -->
  <joint name="wrist_mounted_camera_color_joint" type="fixed">
    <origin rpy="0 0 0" xyz="0 0.015 0"/>
    <parent link="wrist_mounted_camera_link"/>
    <child link="wrist_mounted_camera_color_frame"/>
  </joint>
  <link name="wrist_mounted_camera_color_frame"/>
  <joint name="wrist_mounted_camera_color_optical_joint" type="fixed">
    <origin rpy="-1.5707963267948966 0 -1.5707963267948966" xyz="0 0 0"/>
    <parent link="wrist_mounted_camera_color_frame"/>
    <child link="wrist_mounted_camera_color_optical_frame"/>
  </joint>
  <link name="wrist_mounted_camera_color_optical_frame"/>
  <gazebo reference="wrist_mounted_camera_color_frame">
    <sensor name="wrist_mounted_camera_rgbd_sensor" type="rgbd_camera">
      <camera>
        <horizontal_fov>1.047</horizontal_fov>
        <image>
          <width>640</width>
          <height>480</height>
          <format>RGB_INT8</format>
        </image>
        <clip>
          <near>0.1</near>
          <far>5</far>
        </clip>
        <distortion>
          <k1>0.0</k1>
          <k2>0.0</k2>
          <k3>0.0</k3>
          <p1>0.0</p1>
          <p2>0.0</p2>
          <center>0.5 0.5</center>
        </distortion>
        <lens>
          <intrinsics>
            <fx>554.25469</fx>
            <fy>554.25469</fy>
            <cx>320.5</cx>
            <cy>240.5</cy>
            <s>0</s>
          </intrinsics>
          <!-- These need to match the intrinsics above or
            Ignition will default to different default values -->
          <projection>
            <p_fx>554.25469</p_fx>
            <p_fy>554.25469</p_fy>
            <p_cx>320.5</p_cx>
            <p_cy>240.5</p_cy>
            <tx>0</tx>
            <ty>0</ty>
          </projection>
        </lens>
        <noise>
          <type>gaussian</type>
          <mean>0</mean>
          <stddev>0.00</stddev>
        </noise>
        <depth_camera>
          <clip>
            <near>0.25</near>
            <far>5</far>
          </clip>
        </depth_camera>
        <optical_frame_id>wrist_mounted_camera_color_optical_frame</optical_frame_id>
      </camera>
      <ignition_frame_id>wrist_mounted_camera_color_frame</ignition_frame_id>
      <always_on>1</always_on>
      <update_rate>6</update_rate>
      <visualize>false</visualize>
      <topic>wrist_mounted_camera</topic>
      <enable_metrics>false</enable_metrics>
    </sensor>
  </gazebo>
  <joint name="ur_to_robotiq_joint" type="fixed">
    <!-- The parent link must be read from the robot model it is attached to. -->
    <parent link="realsense_camera_adapter_tool0"/>
    <child link="ur_to_robotiq_link"/>
    <origin rpy="0 0 0" xyz="0 0 0"/>
  </joint>
  <link name="ur_to_robotiq_link">
    <visual>
      <origin rpy="0 0 0" xyz="0 0 0"/>
      <geometry>
        <mesh filename="package://robotiq_description/meshes/collision/2f_85/ur_to_robotiq_adapter.stl"/>
      </geometry>
    </visual>
    <collision>
      <origin rpy="0 0 0" xyz="0 0 0"/>
      <geometry>
        <mesh filename="package://robotiq_description/meshes/collision/2f_85/ur_to_robotiq_adapter.stl"/>
      </geometry>
    </collision>
    <inertial>
      <mass value="0.01"/>
      <origin xyz="0 0 0"/>
      <inertia ixx="0.000044" ixy="0.0" ixz="0.0" iyy="0.000027" iyz="0.0" izz="0.000027"/>
    </inertial>
  </link>
  <joint name="gripper_side_joint" type="fixed">
    <parent link="ur_to_robotiq_link"/>
    <child link="gripper_mount_link"/>
    <!-- <origin xyz="0 0 0.011" rpy="0 ${-pi/2} ${pi/2}"/> -->
    <origin rpy="0 0 0" xyz="0 0 0.011"/>
  </joint>
  <link name="gripper_mount_link"/>
  <ros2_control name="epick_driver_ros2_control" type="system">
    <hardware>
      <plugin>epick_driver/EpickGripperHardwareInterface</plugin>
      <!-- Serial connection parameters ////////////////////////////////// -->
      <param name="usb_port">/dev/ttyUSB0</param>
      <param name="baud_rate">115200</param>
      <param name="timeout">0.2</param>
      <!-- Gripper parameters /////////////////////////////////////////// -->
      <!-- Set use_dummy to true to connect to a dummy driver for testing purposes. -->
      <param name="use_dummy">True</param>
      <!-- The address of the gripper. -->
      <param name="slave_address">0x9</param>
      <!-- The gripper operation mode: AutomaticMode or AdvancedMode. -->
      <param name="mode">AdvancedMode</param>
      <!-- The following parameters are only required for the AdvancedMode. -->
      <param name="grip_max_vacuum_pressure">-60</param>
      <param name="grip_min_vacuum_pressure">-10</param>
      <param name="grip_timeout">25.0</param>
      <param name="release_timeout">2.0</param>
    </hardware>
    <gpio name="gripper">
      <!--
          Command interface to control the gripper:
          1.0 = grip
          0.0 = release
        -->
      <command_interface name="position"/>
      <!--
          State interface that follows the value of the gripper/grip_cmd
          command interface:
          1.0 = successful grip
          0.0 = successful release
        -->
      <state_interface name="position"/>
      <!--
          Return the object detection status:
          0.0 = unknown
          1.0 = object detected at minimum pressure
          2.0 = object detected at maximum pressure
          3.0 = no object detected
        -->
      <state_interface name="object_detection_status"/>
    </gpio>
    <!--
        This is optional configuration if you want to publish the state of the
        gripper as a joint state interface.
      -->
    <joint name="gripper">
      <!--
          State interface that follows the value of the gripper/grip_cmd
          command interface:
          1.0 = successful grip
          0.0 = successful release
        -->
      <state_interface name="position"/>
    </joint>
  </ros2_control>
  <!-- Base Link -->
  <link name="epick_base_link"/>
  <joint name="gripper_mount_link_to_epick_base_link" type="fixed">
    <parent link="gripper_mount_link"/>
    <child link="epick_base_link"/>
    <origin rpy="0 0 0" xyz="0 0 0"/>
  </joint>
  <!-- EPick Body -->
  <link name="epick_body">
    <visual>
      <!-- Shifted backwards since the mesh origin is at the base end -->
      <origin rpy="0 0 0" xyz="0 0 -0.05115"/>
      <geometry>
        <mesh filename="package://epick_description/meshes/visual/epick_body.stl" scale="0.001 0.001 0.001"/>
      </geometry>
      <material name="epick_gray">
        <color rgba="0.25 0.25 0.25 1"/>
      </material>
    </visual>
    <collision>
      <origin rpy="0 0 0" xyz="0 0 0"/>
      <geometry>
        <cylinder length="0.1023" radius="0.044"/>
      </geometry>
    </collision>
  </link>
  <joint name="epick_base_link_to_epick_body" type="fixed">
    <parent link="epick_base_link"/>
    <child link="epick_body"/>
    <origin rpy="0 0 0" xyz="0 0 0.05115"/>
  </joint>
  <link name="epick_extension">
    <visual>
      <origin rpy="0 0 0" xyz="0 0 0"/>
      <geometry>
        <cylinder length="0.088" radius="0.005"/>
      </geometry>
      <material name="">
        <color rgba="0.25 0.25 0.25 1"/>
      </material>
    </visual>
    <collision>
      <origin rpy="0 0 0" xyz="0 0 0"/>
      <geometry>
        <cylinder length="0.088" radius="0.005"/>
      </geometry>
    </collision>
  </link>
  <joint name="epick_body_to_epick_extension" type="fixed">
    <parent link="epick_body"/>
    <child link="epick_extension"/>
    <origin rpy="0 0 0" xyz="0 0 0.09515"/>
  </joint>
  <link name="epick_suction_cup">
    <visual>
      <origin rpy="0 0 0" xyz="0 0 0"/>
      <geometry>
        <cylinder length="0.015" radius="0.012"/>
      </geometry>
      <material name="">
        <color rgba="0.25 0.25 0.25 1"/>
      </material>
    </visual>
    <collision>
      <origin rpy="0 0 0" xyz="0 0 0"/>
      <geometry>
        <cylinder length="0.015" radius="0.012"/>
      </geometry>
    </collision>
  </link>
  <joint name="epick_extension_to_epick_suction_cup" type="fixed">
    <parent link="epick_extension"/>
    <child link="epick_suction_cup"/>
    <origin rpy="0 0 0" xyz="0 0 0.0515"/>
  </joint>
  <!-- TIP Frame -->
  <!-- represents the outmost point of the collision geometry -->
  <link name="epick_tip"/>
  <joint name="epick_suction_cup_to_epick_tip" type="fixed">
    <parent link="epick_suction_cup"/>
    <child link="epick_tip"/>
    <origin rpy="0 0 0" xyz="0 0 0.0075"/>
  </joint>
  <!-- TCP Frame -->
  <!-- contact point to use for IK, Z-axis points "forwards", recessed by tcp_stroke_compensation -->
  <link name="epick_tcp"/>
  <joint name="epick_tip_to_epick_tcp" type="fixed">
    <parent link="epick_tip"/>
    <child link="epick_tcp"/>
    <origin rpy="0 0 0" xyz="0 0 -0.005"/>
  </joint>
  <!-- To allow MoveIt to actuate the gripper as part of a trajectory, we need to include a fake "joint" in the URDF corresponding to the Epick's vacuum state. -->
  <link name="epick_vacuum_state">
    <inertial>
      <mass value="0.01"/>
      <origin xyz="0 0 0"/>
      <inertia ixx="0.00001" ixy="0.0" ixz="0.0" iyy="0.00001" iyz="0.0" izz="0.00001"/>
    </inertial>
  </link>
  <joint name="gripper" type="revolute">
    <origin rpy="0 0 0" xyz="0 0 0"/>
    <parent link="epick_tcp"/>
    <child link="epick_vacuum_state"/>
    <limit effort="30" lower="0.0" upper="1.0" velocity="1.0"/>
  </joint>
  <!-- Grasp link at EPick TCP -->
  <link name="grasp_link"/>
  <joint name="grasp_link_joint" type="fixed">
    <parent link="epick_tcp"/>
    <child link="grasp_link"/>
    <origin rpy="0.0 0.0 0.0" xyz="0.0 0.0 0"/>
  </joint>
  <!-- Workcell (80/20 aluminum extrusion frame) -->
  <!-- robot_mount in the Locus config is at xyz="0.28 -0.026 -0.2" rpy="0 0 pi/2" from workcell.
         Since our robot is at world origin, we place the workcell at the inverse transform. -->
  <link name="workcell">
    <visual>
      <origin rpy="0 0 0" xyz="0 0 0"/>
      <geometry>
        <mesh filename="package://picknik_009_ur5e_config/meshes/workcell_no_totes.stl"/>
      </geometry>
      <material name="workcell_material">
        <color rgba="0.792 0.820 0.933 1"/>
      </material>
    </visual>
    <collision>
      <origin rpy="0 0 0" xyz="0 0 0"/>
      <geometry>
        <mesh filename="package://picknik_009_ur5e_config/meshes/workcell_no_totes.stl"/>
      </geometry>
    </collision>
  </link>
  <joint name="world_to_workcell" type="fixed">
    <parent link="world"/>
    <child link="workcell"/>
    <origin rpy="0 0 -1.5707963267948966" xyz="0.026 0.28 0.2"/>
  </joint>

  <mujoco model="ur5e">
    <compiler fusestatic="false" discardvisual="false" />
    <option integrator="implicitfast">
      <flag multiccd="enable" />
    </option>
  </mujoco>

</robot>
